2018-05-09 17:52:53,128 ERROR: Exception on /sendpost [GET] [in /usr/local/Cellar/python3/3.6.4_2/Frameworks/Python.framework/Versions/3.6/lib/python3.6/site-packages/flask/app.py:1560]
Traceback (most recent call last):
  File "/usr/local/Cellar/python3/3.6.4_2/Frameworks/Python.framework/Versions/3.6/lib/python3.6/site-packages/flask/app.py", line 1982, in wsgi_app
    response = self.full_dispatch_request()
  File "/usr/local/Cellar/python3/3.6.4_2/Frameworks/Python.framework/Versions/3.6/lib/python3.6/site-packages/flask/app.py", line 1614, in full_dispatch_request
    rv = self.handle_user_exception(e)
  File "/usr/local/Cellar/python3/3.6.4_2/Frameworks/Python.framework/Versions/3.6/lib/python3.6/site-packages/flask/app.py", line 1517, in handle_user_exception
    reraise(exc_type, exc_value, tb)
  File "/usr/local/Cellar/python3/3.6.4_2/Frameworks/Python.framework/Versions/3.6/lib/python3.6/site-packages/flask/_compat.py", line 33, in reraise
    raise value
  File "/usr/local/Cellar/python3/3.6.4_2/Frameworks/Python.framework/Versions/3.6/lib/python3.6/site-packages/flask/app.py", line 1612, in full_dispatch_request
    rv = self.dispatch_request()
  File "/usr/local/Cellar/python3/3.6.4_2/Frameworks/Python.framework/Versions/3.6/lib/python3.6/site-packages/flask/app.py", line 1598, in dispatch_request
    return self.view_functions[rule.endpoint](**req.view_args)
  File "/usr/local/Cellar/python3/3.6.4_2/Frameworks/Python.framework/Versions/3.6/lib/python3.6/site-packages/flask_login/utils.py", line 261, in decorated_view
    return func(*args, **kwargs)
  File "/Users/xian/development/cloudApplications/CloudFinal/app/routes.py", line 214, in sendpost
    send_post_email(user=current_user, post=post,date=time,author=author)
NameError: name 'time' is not defined
2018-05-09 17:53:31,162 INFO: Microblog startup [in /Users/xian/development/cloudApplications/CloudFinal/app/__init__.py:52]
2018-05-09 17:53:37,605 ERROR: Exception on /sendpost [GET] [in /usr/local/Cellar/python3/3.6.4_2/Frameworks/Python.framework/Versions/3.6/lib/python3.6/site-packages/flask/app.py:1560]
Traceback (most recent call last):
  File "/usr/local/Cellar/python3/3.6.4_2/Frameworks/Python.framework/Versions/3.6/lib/python3.6/site-packages/flask/app.py", line 1982, in wsgi_app
    response = self.full_dispatch_request()
  File "/usr/local/Cellar/python3/3.6.4_2/Frameworks/Python.framework/Versions/3.6/lib/python3.6/site-packages/flask/app.py", line 1614, in full_dispatch_request
    rv = self.handle_user_exception(e)
  File "/usr/local/Cellar/python3/3.6.4_2/Frameworks/Python.framework/Versions/3.6/lib/python3.6/site-packages/flask/app.py", line 1517, in handle_user_exception
    reraise(exc_type, exc_value, tb)
  File "/usr/local/Cellar/python3/3.6.4_2/Frameworks/Python.framework/Versions/3.6/lib/python3.6/site-packages/flask/_compat.py", line 33, in reraise
    raise value
  File "/usr/local/Cellar/python3/3.6.4_2/Frameworks/Python.framework/Versions/3.6/lib/python3.6/site-packages/flask/app.py", line 1612, in full_dispatch_request
    rv = self.dispatch_request()
  File "/usr/local/Cellar/python3/3.6.4_2/Frameworks/Python.framework/Versions/3.6/lib/python3.6/site-packages/flask/app.py", line 1598, in dispatch_request
    return self.view_functions[rule.endpoint](**req.view_args)
  File "/usr/local/Cellar/python3/3.6.4_2/Frameworks/Python.framework/Versions/3.6/lib/python3.6/site-packages/flask_login/utils.py", line 261, in decorated_view
    return func(*args, **kwargs)
  File "/Users/xian/development/cloudApplications/CloudFinal/app/routes.py", line 214, in sendpost
    send_post_email(user=current_user, post=post,date=time,author=author)
  File "/Users/xian/development/cloudApplications/CloudFinal/app/email.py", line 35, in send_post_email
    user=user, token=token),
NameError: name 'token' is not defined
2018-05-09 17:55:12,169 INFO: Microblog startup [in /Users/xian/development/cloudApplications/CloudFinal/app/__init__.py:52]
2018-05-09 17:55:15,734 ERROR: Exception on /sendpost [GET] [in /usr/local/Cellar/python3/3.6.4_2/Frameworks/Python.framework/Versions/3.6/lib/python3.6/site-packages/flask/app.py:1560]
Traceback (most recent call last):
  File "/usr/local/Cellar/python3/3.6.4_2/Frameworks/Python.framework/Versions/3.6/lib/python3.6/site-packages/flask/app.py", line 1982, in wsgi_app
    response = self.full_dispatch_request()
  File "/usr/local/Cellar/python3/3.6.4_2/Frameworks/Python.framework/Versions/3.6/lib/python3.6/site-packages/flask/app.py", line 1614, in full_dispatch_request
    rv = self.handle_user_exception(e)
  File "/usr/local/Cellar/python3/3.6.4_2/Frameworks/Python.framework/Versions/3.6/lib/python3.6/site-packages/flask/app.py", line 1517, in handle_user_exception
    reraise(exc_type, exc_value, tb)
  File "/usr/local/Cellar/python3/3.6.4_2/Frameworks/Python.framework/Versions/3.6/lib/python3.6/site-packages/flask/_compat.py", line 33, in reraise
    raise value
  File "/usr/local/Cellar/python3/3.6.4_2/Frameworks/Python.framework/Versions/3.6/lib/python3.6/site-packages/flask/app.py", line 1612, in full_dispatch_request
    rv = self.dispatch_request()
  File "/usr/local/Cellar/python3/3.6.4_2/Frameworks/Python.framework/Versions/3.6/lib/python3.6/site-packages/flask/app.py", line 1598, in dispatch_request
    return self.view_functions[rule.endpoint](**req.view_args)
  File "/usr/local/Cellar/python3/3.6.4_2/Frameworks/Python.framework/Versions/3.6/lib/python3.6/site-packages/flask_login/utils.py", line 261, in decorated_view
    return func(*args, **kwargs)
  File "/Users/xian/development/cloudApplications/CloudFinal/app/routes.py", line 214, in sendpost
    send_post_email(user=current_user, post=post,date=time,author=author)
  File "/Users/xian/development/cloudApplications/CloudFinal/app/email.py", line 35, in send_post_email
    user=user, author=author, time=date,post=post),
  File "/usr/local/Cellar/python3/3.6.4_2/Frameworks/Python.framework/Versions/3.6/lib/python3.6/site-packages/flask/templating.py", line 133, in render_template
    return _render(ctx.app.jinja_env.get_or_select_template(template_name_or_list),
  File "/usr/local/Cellar/python3/3.6.4_2/Frameworks/Python.framework/Versions/3.6/lib/python3.6/site-packages/jinja2/environment.py", line 869, in get_or_select_template
    return self.get_template(template_name_or_list, parent, globals)
  File "/usr/local/Cellar/python3/3.6.4_2/Frameworks/Python.framework/Versions/3.6/lib/python3.6/site-packages/jinja2/environment.py", line 830, in get_template
    return self._load_template(name, self.make_globals(globals))
  File "/usr/local/Cellar/python3/3.6.4_2/Frameworks/Python.framework/Versions/3.6/lib/python3.6/site-packages/jinja2/environment.py", line 804, in _load_template
    template = self.loader.load(self, name, globals)
  File "/usr/local/Cellar/python3/3.6.4_2/Frameworks/Python.framework/Versions/3.6/lib/python3.6/site-packages/jinja2/loaders.py", line 113, in load
    source, filename, uptodate = self.get_source(environment, name)
  File "/usr/local/Cellar/python3/3.6.4_2/Frameworks/Python.framework/Versions/3.6/lib/python3.6/site-packages/flask/templating.py", line 57, in get_source
    return self._get_source_fast(environment, template)
  File "/usr/local/Cellar/python3/3.6.4_2/Frameworks/Python.framework/Versions/3.6/lib/python3.6/site-packages/flask/templating.py", line 85, in _get_source_fast
    raise TemplateNotFound(template)
jinja2.exceptions.TemplateNotFound: email/post-email.txt
2018-05-09 17:55:48,319 INFO: Microblog startup [in /Users/xian/development/cloudApplications/CloudFinal/app/__init__.py:52]
2018-05-09 17:56:47,961 INFO: Microblog startup [in /Users/xian/development/cloudApplications/CloudFinal/app/__init__.py:52]
2018-05-09 20:05:17,003 INFO: Microblog startup [in /Users/xian/development/cloudApplications/CloudFinal/app/__init__.py:52]
2018-05-09 20:05:32,114 INFO: Microblog startup [in /Users/xian/development/cloudApplications/CloudFinal/app/__init__.py:52]
2018-05-09 20:06:35,796 INFO: Microblog startup [in /Users/xian/development/cloudApplications/CloudFinal/app/__init__.py:52]
2018-05-09 20:08:23,674 INFO: Microblog startup [in /Users/xian/development/cloudApplications/CloudFinal/app/__init__.py:52]
2018-05-09 20:12:44,033 INFO: Microblog startup [in /Users/xian/development/cloudApplications/CloudFinal/app/__init__.py:52]
2018-05-09 20:12:50,636 ERROR: Exception on /sendpost [GET] [in /usr/local/Cellar/python3/3.6.4_2/Frameworks/Python.framework/Versions/3.6/lib/python3.6/site-packages/flask/app.py:1560]
Traceback (most recent call last):
  File "/usr/local/Cellar/python3/3.6.4_2/Frameworks/Python.framework/Versions/3.6/lib/python3.6/site-packages/flask/app.py", line 1982, in wsgi_app
    response = self.full_dispatch_request()
  File "/usr/local/Cellar/python3/3.6.4_2/Frameworks/Python.framework/Versions/3.6/lib/python3.6/site-packages/flask/app.py", line 1615, in full_dispatch_request
    return self.finalize_request(rv)
  File "/usr/local/Cellar/python3/3.6.4_2/Frameworks/Python.framework/Versions/3.6/lib/python3.6/site-packages/flask/app.py", line 1630, in finalize_request
    response = self.make_response(rv)
  File "/usr/local/Cellar/python3/3.6.4_2/Frameworks/Python.framework/Versions/3.6/lib/python3.6/site-packages/flask/app.py", line 1725, in make_response
    raise ValueError('View function did not return a response')
ValueError: View function did not return a response
2018-05-09 20:14:49,641 INFO: Microblog startup [in /Users/xian/development/cloudApplications/CloudFinal/app/__init__.py:52]
2018-05-09 20:16:09,013 INFO: Microblog startup [in /Users/xian/development/cloudApplications/CloudFinal/app/__init__.py:52]
2018-05-09 20:16:43,175 INFO: Microblog startup [in /Users/xian/development/cloudApplications/CloudFinal/app/__init__.py:52]
2018-05-09 20:24:53,055 INFO: Microblog startup [in /Users/xian/development/cloudApplications/CloudFinal/app/__init__.py:52]
